<sdf version='1.7'>
  <world name='default'>
    <light name='sun' type='directional'>
      <cast_shadows>1</cast_shadows>
      <pose>0 0 10 0 -0 0</pose>
      <diffuse>0.8 0.8 0.8 1</diffuse>
      <specular>0.2 0.2 0.2 1</specular>
      <attenuation>
        <range>1000</range>
        <constant>0.9</constant>
        <linear>0.01</linear>
        <quadratic>0.001</quadratic>
      </attenuation>
      <direction>-0.5 0.1 -0.9</direction>
      <spot>
        <inner_angle>0</inner_angle>
        <outer_angle>0</outer_angle>
        <falloff>0</falloff>
      </spot>
    </light>
    <model name='ground_plane'>
      <static>1</static>
      <link name='link'>
        <collision name='collision'>
          <geometry>
            <plane>
              <normal>0 0 1</normal>
              <size>100 100</size>
            </plane>
          </geometry>
          <surface>
            <friction>
              <ode>
                <mu>100</mu>
                <mu2>50</mu2>
              </ode>
              <torsional>
                <ode/>
              </torsional>
            </friction>
            <contact>
              <ode/>
            </contact>
            <bounce/>
          </surface>
          <max_contacts>10</max_contacts>
        </collision>
        <visual name='visual'>
          <cast_shadows>0</cast_shadows>
          <geometry>
            <plane>
              <normal>0 0 1</normal>
              <size>100 100</size>
            </plane>
          </geometry>
          <material>
            <script>
              <uri>file://media/materials/scripts/gazebo.material</uri>
              <name>Gazebo/Grey</name>
            </script>
          </material>
        </visual>
        <self_collide>0</self_collide>
        <enable_wind>0</enable_wind>
        <kinematic>0</kinematic>
      </link>
    </model>
    <gravity>0 0 -9.8</gravity>
    <magnetic_field>6e-06 2.3e-05 -4.2e-05</magnetic_field>
    <atmosphere type='adiabatic'/>
    <physics type='ode'>
      <max_step_size>0.001</max_step_size>
      <real_time_factor>1</real_time_factor>
      <real_time_update_rate>1000</real_time_update_rate>
    </physics>
    <scene>
      <ambient>0.4 0.4 0.4 1</ambient>
      <background>0.7 0.7 0.7 1</background>
      <shadows>1</shadows>
    </scene>
    <wind/>
    <spherical_coordinates>
      <surface_model>EARTH_WGS84</surface_model>
      <latitude_deg>0</latitude_deg>
      <longitude_deg>0</longitude_deg>
      <elevation>0</elevation>
      <heading_deg>0</heading_deg>
    </spherical_coordinates>
    <model name='cloverleaf_interchange'>
      <static>1</static>
      <link name='link'>
        <collision name='collision'>
          <geometry>
            <mesh>
              <uri>model://cloverleaf_interchange/meshes/cloverleaf.obj</uri>
              <scale>0.0254 0.0254 0.0254</scale>
            </mesh>
          </geometry>
          <max_contacts>10</max_contacts>
          <surface>
            <contact>
              <ode/>
            </contact>
            <bounce/>
            <friction>
              <torsional>
                <ode/>
              </torsional>
              <ode/>
            </friction>
          </surface>
        </collision>
        <visual name='visual'>
          <geometry>
            <mesh>
              <uri>model://cloverleaf_interchange/meshes/cloverleaf.obj</uri>
              <scale>0.0254 0.0254 0.0254</scale>
            </mesh>
          </geometry>
        </visual>
        <self_collide>0</self_collide>
        <enable_wind>0</enable_wind>
        <kinematic>0</kinematic>
      </link>
      <pose>-0.129569 0.117381 0 0 -0 0</pose>
    </model>
    <model name='rover'>
      <link name='link_1'>
        <inertial>
          <mass>1</mass>
          <inertia>
            <ixx>0.166667</ixx>
            <ixy>0</ixy>
            <ixz>0</ixz>
            <iyy>0.166667</iyy>
            <iyz>0</iyz>
            <izz>0.166667</izz>
          </inertia>
          <pose>0 0 0 0 -0 0</pose>
        </inertial>
        <pose>-0.007755 0.056757 0.689661 0 -0 0</pose>
        <visual name='visual'>
          <pose>0 0 0 0 -0 0</pose>
          <geometry>
            <mesh>
              <uri>/home/luqman/ros2_workspace/src/autonomous_rover/meshes/small/camera.stl</uri>
              <scale>1 1 1</scale>
            </mesh>
          </geometry>
          <material>
            <lighting>1</lighting>
            <script>
              <uri>file://media/materials/scripts/gazebo.material</uri>
              <name>Gazebo/Grey</name>
            </script>
            <shader type='pixel'/>
            <emissive>0 0 0 1</emissive>
          </material>
          <transparency>0</transparency>
          <cast_shadows>1</cast_shadows>
        </visual>
        <collision name='collision'>
          <laser_retro>0</laser_retro>
          <max_contacts>10</max_contacts>
          <pose>0 0 0 0 -0 0</pose>
          <geometry>
            <mesh>
              <uri>/home/luqman/ros2_workspace/src/autonomous_rover/meshes/small/camera.stl</uri>
              <scale>1 1 1</scale>
            </mesh>
          </geometry>
          <surface>
            <friction>
              <ode>
                <mu>1</mu>
                <mu2>1</mu2>
                <fdir1>0 0 0</fdir1>
                <slip1>0</slip1>
                <slip2>0</slip2>
              </ode>
              <torsional>
                <coefficient>1</coefficient>
                <patch_radius>0</patch_radius>
                <surface_radius>0</surface_radius>
                <use_patch_radius>1</use_patch_radius>
                <ode>
                  <slip>0</slip>
                </ode>
              </torsional>
            </friction>
            <bounce>
              <restitution_coefficient>0</restitution_coefficient>
              <threshold>1e+06</threshold>
            </bounce>
            <contact>
              <collide_without_contact>0</collide_without_contact>
              <collide_without_contact_bitmask>1</collide_without_contact_bitmask>
              <collide_bitmask>1</collide_bitmask>
              <ode>
                <soft_cfm>0</soft_cfm>
                <soft_erp>0.2</soft_erp>
                <kp>1e+13</kp>
                <kd>1</kd>
                <max_vel>0.01</max_vel>
                <min_depth>0</min_depth>
              </ode>
              <bullet>
                <split_impulse>1</split_impulse>
                <split_impulse_penetration_threshold>-0.01</split_impulse_penetration_threshold>
                <soft_cfm>0</soft_cfm>
                <soft_erp>0.2</soft_erp>
                <kp>1e+13</kp>
                <kd>1</kd>
              </bullet>
            </contact>
          </surface>
        </collision>
        <self_collide>0</self_collide>
        <enable_wind>0</enable_wind>
        <kinematic>0</kinematic>
      </link>
      <model name='rover'>
        <link name='link_base'>
          <inertial>
            <mass>1</mass>
            <inertia>
              <ixx>0.166667</ixx>
              <ixy>0</ixy>
              <ixz>0</ixz>
              <iyy>0.166667</iyy>
              <iyz>0</iyz>
              <izz>0.166667</izz>
            </inertia>
            <pose>0 0 0 0 -0 0</pose>
          </inertial>
          <pose>-0.015457 -0.017859 0.702123 0 -0 0</pose>
          <gravity>1</gravity>
          <self_collide>0</self_collide>
          <kinematic>0</kinematic>
          <enable_wind>0</enable_wind>
          <visual name='visual'>
            <pose>0 0 0 0 -0 0</pose>
            <geometry>
              <mesh>
                <uri>/home/luqman/ros2_workspace/src/autonomous_rover/meshes/small/base.stl</uri>
                <scale>1 1 1</scale>
              </mesh>
            </geometry>
            <material>
              <lighting>1</lighting>
              <script>
                <uri>file://media/materials/scripts/gazebo.material</uri>
                <name>Gazebo/Red</name>
              </script>
              <shader type='pixel'>
                <normal_map>__default__</normal_map>
              </shader>
              <ambient>0 0 0 1</ambient>
              <diffuse>0 0 0 1</diffuse>
              <specular>0.1 0.1 0.1 1</specular>
              <emissive>0 0 0 1</emissive>
            </material>
            <transparency>0</transparency>
            <cast_shadows>1</cast_shadows>
          </visual>
          <collision name='collision'>
            <laser_retro>0</laser_retro>
            <max_contacts>10</max_contacts>
            <pose>0 0 0 0 -0 0</pose>
            <geometry>
              <mesh>
                <uri>/home/luqman/ros2_workspace/src/autonomous_rover/meshes/small/base.stl</uri>
                <scale>1 1 1</scale>
              </mesh>
            </geometry>
            <surface>
              <friction>
                <ode>
                  <mu>1</mu>
                  <mu2>1</mu2>
                  <fdir1>0 0 0</fdir1>
                  <slip1>0</slip1>
                  <slip2>0</slip2>
                </ode>
                <torsional>
                  <coefficient>1</coefficient>
                  <patch_radius>0</patch_radius>
                  <surface_radius>0</surface_radius>
                  <use_patch_radius>1</use_patch_radius>
                  <ode>
                    <slip>0</slip>
                  </ode>
                </torsional>
              </friction>
              <bounce>
                <restitution_coefficient>0</restitution_coefficient>
                <threshold>1e+06</threshold>
              </bounce>
              <contact>
                <collide_without_contact>0</collide_without_contact>
                <collide_without_contact_bitmask>1</collide_without_contact_bitmask>
                <collide_bitmask>1</collide_bitmask>
                <ode>
                  <soft_cfm>0</soft_cfm>
                  <soft_erp>0.2</soft_erp>
                  <kp>1e+13</kp>
                  <kd>1</kd>
                  <max_vel>0.01</max_vel>
                  <min_depth>0</min_depth>
                </ode>
                <bullet>
                  <split_impulse>1</split_impulse>
                  <split_impulse_penetration_threshold>-0.01</split_impulse_penetration_threshold>
                  <soft_cfm>0</soft_cfm>
                  <soft_erp>0.2</soft_erp>
                  <kp>1e+13</kp>
                  <kd>1</kd>
                </bullet>
              </contact>
            </surface>
          </collision>
        </link>
        <link name='link_upper_body'>
          <inertial>
            <mass>1</mass>
            <inertia>
              <ixx>0.166667</ixx>
              <ixy>0</ixy>
              <ixz>0</ixz>
              <iyy>0.166667</iyy>
              <iyz>0</iyz>
              <izz>0.166667</izz>
            </inertia>
            <pose>0 0 0 0 -0 0</pose>
          </inertial>
          <pose>-0.007584 0.188222 0.745735 0 -0 0</pose>
          <gravity>1</gravity>
          <self_collide>0</self_collide>
          <kinematic>0</kinematic>
          <enable_wind>0</enable_wind>
          <visual name='visual'>
            <pose>0 0 0 0 -0 0</pose>
            <geometry>
              <mesh>
                <uri>/home/luqman/ros2_workspace/src/autonomous_rover/meshes/small/upper_body.stl</uri>
                <scale>1 1 1</scale>
              </mesh>
            </geometry>
            <material>
              <lighting>1</lighting>
              <script>
                <uri>file://media/materials/scripts/gazebo.material</uri>
                <name>Gazebo/White</name>
              </script>
              <shader type='pixel'>
                <normal_map>__default__</normal_map>
              </shader>
              <ambient>0 0 0 1</ambient>
              <diffuse>0 0 0 1</diffuse>
              <specular>0.1 0.1 0.1 1</specular>
              <emissive>0 0 0 1</emissive>
            </material>
            <transparency>0</transparency>
            <cast_shadows>1</cast_shadows>
          </visual>
          <collision name='collision'>
            <laser_retro>0</laser_retro>
            <max_contacts>10</max_contacts>
            <pose>0 0 0 0 -0 0</pose>
            <geometry>
              <mesh>
                <uri>/home/luqman/ros2_workspace/src/autonomous_rover/meshes/small/upper_body.stl</uri>
                <scale>1 1 1</scale>
              </mesh>
            </geometry>
            <surface>
              <friction>
                <ode>
                  <mu>1</mu>
                  <mu2>1</mu2>
                  <fdir1>0 0 0</fdir1>
                  <slip1>0</slip1>
                  <slip2>0</slip2>
                </ode>
                <torsional>
                  <coefficient>1</coefficient>
                  <patch_radius>0</patch_radius>
                  <surface_radius>0</surface_radius>
                  <use_patch_radius>1</use_patch_radius>
                  <ode>
                    <slip>0</slip>
                  </ode>
                </torsional>
              </friction>
              <bounce>
                <restitution_coefficient>0</restitution_coefficient>
                <threshold>1e+06</threshold>
              </bounce>
              <contact>
                <collide_without_contact>0</collide_without_contact>
                <collide_without_contact_bitmask>1</collide_without_contact_bitmask>
                <collide_bitmask>1</collide_bitmask>
                <ode>
                  <soft_cfm>0</soft_cfm>
                  <soft_erp>0.2</soft_erp>
                  <kp>1e+13</kp>
                  <kd>1</kd>
                  <max_vel>0.01</max_vel>
                  <min_depth>0</min_depth>
                </ode>
                <bullet>
                  <split_impulse>1</split_impulse>
                  <split_impulse_penetration_threshold>-0.01</split_impulse_penetration_threshold>
                  <soft_cfm>0</soft_cfm>
                  <soft_erp>0.2</soft_erp>
                  <kp>1e+13</kp>
                  <kd>1</kd>
                </bullet>
              </contact>
            </surface>
          </collision>
        </link>
        <link name='link_wheel_front_right'>
          <inertial>
            <mass>1</mass>
            <inertia>
              <ixx>0.166667</ixx>
              <ixy>0</ixy>
              <ixz>0</ixz>
              <iyy>0.166667</iyy>
              <iyz>0</iyz>
              <izz>0.166667</izz>
            </inertia>
            <pose>0 0 0 0 -0 0</pose>
          </inertial>
          <pose>0.863976 0.765098 0.406418 0 -0 0</pose>
          <gravity>1</gravity>
          <self_collide>0</self_collide>
          <kinematic>0</kinematic>
          <enable_wind>0</enable_wind>
          <visual name='visual'>
            <pose>0 0 0 0 -0 0</pose>
            <geometry>
              <mesh>
                <uri>/home/luqman/ros2_workspace/src/autonomous_rover/meshes/small/wheel.stl</uri>
                <scale>1 1 1</scale>
              </mesh>
            </geometry>
            <material>
              <lighting>1</lighting>
              <script>
                <uri>file://media/materials/scripts/gazebo.material</uri>
                <name>Gazebo/Blue</name>
              </script>
              <shader type='pixel'>
                <normal_map>__default__</normal_map>
              </shader>
              <ambient>0 0 1 1</ambient>
              <diffuse>0 0 1 1</diffuse>
              <specular>0.1 0.1 0.1 1</specular>
              <emissive>0 0 0 1</emissive>
            </material>
            <transparency>0</transparency>
            <cast_shadows>1</cast_shadows>
          </visual>
          <collision name='collision'>
            <laser_retro>0</laser_retro>
            <max_contacts>10</max_contacts>
            <pose>0 0 0 0 -0 0</pose>
            <geometry>
              <mesh>
                <uri>/home/luqman/ros2_workspace/src/autonomous_rover/meshes/small/wheel.stl</uri>
                <scale>1 1 1</scale>
              </mesh>
            </geometry>
            <surface>
              <friction>
                <ode>
                  <mu>1</mu>
                  <mu2>1</mu2>
                  <fdir1>0 0 0</fdir1>
                  <slip1>0</slip1>
                  <slip2>0</slip2>
                </ode>
                <torsional>
                  <coefficient>1</coefficient>
                  <patch_radius>0</patch_radius>
                  <surface_radius>0</surface_radius>
                  <use_patch_radius>1</use_patch_radius>
                  <ode>
                    <slip>0</slip>
                  </ode>
                </torsional>
              </friction>
              <bounce>
                <restitution_coefficient>0</restitution_coefficient>
                <threshold>1e+06</threshold>
              </bounce>
              <contact>
                <collide_without_contact>0</collide_without_contact>
                <collide_without_contact_bitmask>1</collide_without_contact_bitmask>
                <collide_bitmask>1</collide_bitmask>
                <ode>
                  <soft_cfm>0</soft_cfm>
                  <soft_erp>0.2</soft_erp>
                  <kp>1e+13</kp>
                  <kd>1</kd>
                  <max_vel>0.01</max_vel>
                  <min_depth>0</min_depth>
                </ode>
                <bullet>
                  <split_impulse>1</split_impulse>
                  <split_impulse_penetration_threshold>-0.01</split_impulse_penetration_threshold>
                  <soft_cfm>0</soft_cfm>
                  <soft_erp>0.2</soft_erp>
                  <kp>1e+13</kp>
                  <kd>1</kd>
                </bullet>
              </contact>
            </surface>
          </collision>
        </link>
        <link name='link_wheel_back_right'>
          <inertial>
            <mass>1</mass>
            <inertia>
              <ixx>0.166667</ixx>
              <ixy>0</ixy>
              <ixz>0</ixz>
              <iyy>0.166667</iyy>
              <iyz>0</iyz>
              <izz>0.166667</izz>
            </inertia>
            <pose>0 0 0 0 -0 0</pose>
          </inertial>
          <pose>0.870631 -0.858717 0.404479 0 -0 0</pose>
          <gravity>1</gravity>
          <self_collide>0</self_collide>
          <kinematic>0</kinematic>
          <enable_wind>0</enable_wind>
          <visual name='visual'>
            <pose>0 0 0 0 -0 0</pose>
            <geometry>
              <mesh>
                <uri>/home/luqman/ros2_workspace/src/autonomous_rover/meshes/small/wheel.stl</uri>
                <scale>1 1 1</scale>
              </mesh>
            </geometry>
            <material>
              <lighting>1</lighting>
              <script>
                <uri>file://media/materials/scripts/gazebo.material</uri>
                <name>Gazebo/Blue</name>
              </script>
              <shader type='pixel'>
                <normal_map>__default__</normal_map>
              </shader>
              <ambient>0 0 1 1</ambient>
              <diffuse>0 0 1 1</diffuse>
              <specular>0.1 0.1 0.1 1</specular>
              <emissive>0 0 0 1</emissive>
            </material>
            <transparency>0</transparency>
            <cast_shadows>1</cast_shadows>
          </visual>
          <collision name='collision'>
            <laser_retro>0</laser_retro>
            <max_contacts>10</max_contacts>
            <pose>0 0 0 0 -0 0</pose>
            <geometry>
              <mesh>
                <uri>/home/luqman/ros2_workspace/src/autonomous_rover/meshes/small/wheel.stl</uri>
                <scale>1 1 1</scale>
              </mesh>
            </geometry>
            <surface>
              <friction>
                <ode>
                  <mu>1</mu>
                  <mu2>1</mu2>
                  <fdir1>0 0 0</fdir1>
                  <slip1>0</slip1>
                  <slip2>0</slip2>
                </ode>
                <torsional>
                  <coefficient>1</coefficient>
                  <patch_radius>0</patch_radius>
                  <surface_radius>0</surface_radius>
                  <use_patch_radius>1</use_patch_radius>
                  <ode>
                    <slip>0</slip>
                  </ode>
                </torsional>
              </friction>
              <bounce>
                <restitution_coefficient>0</restitution_coefficient>
                <threshold>1e+06</threshold>
              </bounce>
              <contact>
                <collide_without_contact>0</collide_without_contact>
                <collide_without_contact_bitmask>1</collide_without_contact_bitmask>
                <collide_bitmask>1</collide_bitmask>
                <ode>
                  <soft_cfm>0</soft_cfm>
                  <soft_erp>0.2</soft_erp>
                  <kp>1e+13</kp>
                  <kd>1</kd>
                  <max_vel>0.01</max_vel>
                  <min_depth>0</min_depth>
                </ode>
                <bullet>
                  <split_impulse>1</split_impulse>
                  <split_impulse_penetration_threshold>-0.01</split_impulse_penetration_threshold>
                  <soft_cfm>0</soft_cfm>
                  <soft_erp>0.2</soft_erp>
                  <kp>1e+13</kp>
                  <kd>1</kd>
                </bullet>
              </contact>
            </surface>
          </collision>
        </link>
        <link name='link_wheel_back_left'>
          <inertial>
            <mass>1</mass>
            <inertia>
              <ixx>0.166667</ixx>
              <ixy>0</ixy>
              <ixz>0</ixz>
              <iyy>0.166667</iyy>
              <iyz>0</iyz>
              <izz>0.166667</izz>
            </inertia>
            <pose>0 0 0 0 -0 0</pose>
          </inertial>
          <pose>-0.878578 -0.864697 0.401212 0 0 -3.13794</pose>
          <gravity>1</gravity>
          <self_collide>0</self_collide>
          <kinematic>0</kinematic>
          <enable_wind>0</enable_wind>
          <visual name='visual'>
            <pose>0 0 0 0 -0 0</pose>
            <geometry>
              <mesh>
                <uri>/home/luqman/ros2_workspace/src/autonomous_rover/meshes/small/wheel.stl</uri>
                <scale>1 1 1</scale>
              </mesh>
            </geometry>
            <material>
              <lighting>1</lighting>
              <script>
                <uri>file://media/materials/scripts/gazebo.material</uri>
                <name>Gazebo/Blue</name>
              </script>
              <shader type='pixel'>
                <normal_map>__default__</normal_map>
              </shader>
              <ambient>0 0 1 1</ambient>
              <diffuse>0 0 1 1</diffuse>
              <specular>0.1 0.1 0.1 1</specular>
              <emissive>0 0 0 1</emissive>
            </material>
            <transparency>0</transparency>
            <cast_shadows>1</cast_shadows>
          </visual>
          <collision name='collision'>
            <laser_retro>0</laser_retro>
            <max_contacts>10</max_contacts>
            <pose>0 0 0 0 -0 0</pose>
            <geometry>
              <mesh>
                <uri>/home/luqman/ros2_workspace/src/autonomous_rover/meshes/small/wheel.stl</uri>
                <scale>1 1 1</scale>
              </mesh>
            </geometry>
            <surface>
              <friction>
                <ode>
                  <mu>1</mu>
                  <mu2>1</mu2>
                  <fdir1>0 0 0</fdir1>
                  <slip1>0</slip1>
                  <slip2>0</slip2>
                </ode>
                <torsional>
                  <coefficient>1</coefficient>
                  <patch_radius>0</patch_radius>
                  <surface_radius>0</surface_radius>
                  <use_patch_radius>1</use_patch_radius>
                  <ode>
                    <slip>0</slip>
                  </ode>
                </torsional>
              </friction>
              <bounce>
                <restitution_coefficient>0</restitution_coefficient>
                <threshold>1e+06</threshold>
              </bounce>
              <contact>
                <collide_without_contact>0</collide_without_contact>
                <collide_without_contact_bitmask>1</collide_without_contact_bitmask>
                <collide_bitmask>1</collide_bitmask>
                <ode>
                  <soft_cfm>0</soft_cfm>
                  <soft_erp>0.2</soft_erp>
                  <kp>1e+13</kp>
                  <kd>1</kd>
                  <max_vel>0.01</max_vel>
                  <min_depth>0</min_depth>
                </ode>
                <bullet>
                  <split_impulse>1</split_impulse>
                  <split_impulse_penetration_threshold>-0.01</split_impulse_penetration_threshold>
                  <soft_cfm>0</soft_cfm>
                  <soft_erp>0.2</soft_erp>
                  <kp>1e+13</kp>
                  <kd>1</kd>
                </bullet>
              </contact>
            </surface>
          </collision>
        </link>
        <link name='link_wheel_front_left'>
          <inertial>
            <mass>1</mass>
            <inertia>
              <ixx>0.166667</ixx>
              <ixy>0</ixy>
              <ixz>0</ixz>
              <iyy>0.166667</iyy>
              <iyz>0</iyz>
              <izz>0.166667</izz>
            </inertia>
            <pose>0 0 0 0 -0 0</pose>
          </inertial>
          <pose>-0.874885 0.787951 0.397919 0 -0 -3.1356</pose>
          <gravity>1</gravity>
          <self_collide>0</self_collide>
          <kinematic>0</kinematic>
          <enable_wind>0</enable_wind>
          <visual name='visual'>
            <pose>0 0 0 0 -0 0</pose>
            <geometry>
              <mesh>
                <uri>/home/luqman/ros2_workspace/src/autonomous_rover/meshes/small/wheel.stl</uri>
                <scale>1 1 1</scale>
              </mesh>
            </geometry>
            <material>
              <lighting>1</lighting>
              <script>
                <uri>file://media/materials/scripts/gazebo.material</uri>
                <name>Gazebo/Blue</name>
              </script>
              <shader type='pixel'>
                <normal_map>__default__</normal_map>
              </shader>
              <ambient>0 0 1 1</ambient>
              <diffuse>0 0 1 1</diffuse>
              <specular>0.1 0.1 0.1 1</specular>
              <emissive>0 0 0 1</emissive>
            </material>
            <transparency>0</transparency>
            <cast_shadows>1</cast_shadows>
          </visual>
          <collision name='collision'>
            <laser_retro>0</laser_retro>
            <max_contacts>10</max_contacts>
            <pose>0 0 0 0 -0 0</pose>
            <geometry>
              <mesh>
                <uri>/home/luqman/ros2_workspace/src/autonomous_rover/meshes/small/wheel.stl</uri>
                <scale>1 1 1</scale>
              </mesh>
            </geometry>
            <surface>
              <friction>
                <ode>
                  <mu>1</mu>
                  <mu2>1</mu2>
                  <fdir1>0 0 0</fdir1>
                  <slip1>0</slip1>
                  <slip2>0</slip2>
                </ode>
                <torsional>
                  <coefficient>1</coefficient>
                  <patch_radius>0</patch_radius>
                  <surface_radius>0</surface_radius>
                  <use_patch_radius>1</use_patch_radius>
                  <ode>
                    <slip>0</slip>
                  </ode>
                </torsional>
              </friction>
              <bounce>
                <restitution_coefficient>0</restitution_coefficient>
                <threshold>1e+06</threshold>
              </bounce>
              <contact>
                <collide_without_contact>0</collide_without_contact>
                <collide_without_contact_bitmask>1</collide_without_contact_bitmask>
                <collide_bitmask>1</collide_bitmask>
                <ode>
                  <soft_cfm>0</soft_cfm>
                  <soft_erp>0.2</soft_erp>
                  <kp>1e+13</kp>
                  <kd>1</kd>
                  <max_vel>0.01</max_vel>
                  <min_depth>0</min_depth>
                </ode>
                <bullet>
                  <split_impulse>1</split_impulse>
                  <split_impulse_penetration_threshold>-0.01</split_impulse_penetration_threshold>
                  <soft_cfm>0</soft_cfm>
                  <soft_erp>0.2</soft_erp>
                  <kp>1e+13</kp>
                  <kd>1</kd>
                </bullet>
              </contact>
            </surface>
          </collision>
        </link>
        <joint name='W_FL_J' type='revolute'>
          <parent>link_base</parent>
          <child>link_wheel_front_left</child>
          <pose>0 0 0 0 -0 0</pose>
          <axis>
            <xyz>-1 0 0</xyz>
            <limit>
              <lower>-1.79769e+308</lower>
              <upper>1.79769e+308</upper>
              <effort>-1</effort>
              <velocity>-1</velocity>
            </limit>
            <dynamics>
              <spring_reference>0</spring_reference>
              <spring_stiffness>0</spring_stiffness>
              <damping>0</damping>
              <friction>0</friction>
            </dynamics>
          </axis>
          <physics>
            <ode>
              <limit>
                <cfm>0</cfm>
                <erp>0.2</erp>
              </limit>
              <suspension>
                <cfm>0</cfm>
                <erp>0.2</erp>
              </suspension>
            </ode>
          </physics>
        </joint>
        <joint name='W_BL_J' type='revolute'>
          <parent>link_base</parent>
          <child>link_wheel_back_left</child>
          <pose>0 0 0 0 -0 0</pose>
          <axis>
            <xyz>-1 0 0</xyz>
            <limit>
              <lower>-1.79769e+308</lower>
              <upper>1.79769e+308</upper>
              <effort>-1</effort>
              <velocity>-1</velocity>
            </limit>
            <dynamics>
              <spring_reference>0</spring_reference>
              <spring_stiffness>0</spring_stiffness>
              <damping>0</damping>
              <friction>0</friction>
            </dynamics>
          </axis>
          <physics>
            <ode>
              <limit>
                <cfm>0</cfm>
                <erp>0.2</erp>
              </limit>
              <suspension>
                <cfm>0</cfm>
                <erp>0.2</erp>
              </suspension>
            </ode>
          </physics>
        </joint>
        <joint name='W_BR_J' type='revolute'>
          <parent>link_base</parent>
          <child>link_wheel_back_right</child>
          <pose>0 0 0 0 -0 0</pose>
          <axis>
            <xyz>-1 0 0</xyz>
            <limit>
              <lower>-1.79769e+308</lower>
              <upper>1.79769e+308</upper>
              <effort>-1</effort>
              <velocity>-1</velocity>
            </limit>
            <dynamics>
              <spring_reference>0</spring_reference>
              <spring_stiffness>0</spring_stiffness>
              <damping>0</damping>
              <friction>0</friction>
            </dynamics>
          </axis>
          <physics>
            <ode>
              <limit>
                <cfm>0</cfm>
                <erp>0.2</erp>
              </limit>
              <suspension>
                <cfm>0</cfm>
                <erp>0.2</erp>
              </suspension>
            </ode>
          </physics>
        </joint>
        <joint name='W_FR_J' type='revolute'>
          <parent>link_base</parent>
          <child>link_wheel_front_right</child>
          <pose>0 0 0 0 -0 0</pose>
          <axis>
            <xyz>-1 0 0</xyz>
            <limit>
              <lower>-1.79769e+308</lower>
              <upper>1.79769e+308</upper>
              <effort>-1</effort>
              <velocity>-1</velocity>
            </limit>
            <dynamics>
              <spring_reference>0</spring_reference>
              <spring_stiffness>0</spring_stiffness>
              <damping>0</damping>
              <friction>0</friction>
            </dynamics>
          </axis>
          <physics>
            <ode>
              <limit>
                <cfm>0</cfm>
                <erp>0.2</erp>
              </limit>
              <suspension>
                <cfm>0</cfm>
                <erp>0.2</erp>
              </suspension>
            </ode>
          </physics>
        </joint>
        <joint name='Upper_B_J' type='fixed'>
          <parent>link_base</parent>
          <child>link_upper_body</child>
          <pose>0 0 0 0 -0 0</pose>
          <physics>
            <ode>
              <limit>
                <cfm>0</cfm>
                <erp>0.2</erp>
              </limit>
              <suspension>
                <cfm>0</cfm>
                <erp>0.2</erp>
              </suspension>
            </ode>
          </physics>
        </joint>
        <static>0</static>
        <allow_auto_disable>1</allow_auto_disable>
        <pose>0.007756 -0.056756 -0.689665 0 -0 0</pose>
      </model>
      <joint name='link_upper_body_JOINT_0' type='fixed'>
        <parent>rover::link_upper_body</parent>
        <child>link_1</child>
        <pose>0 0 0 0 -0 0</pose>
        <physics>
          <ode>
            <limit>
              <cfm>0</cfm>
              <erp>0.2</erp>
            </limit>
            <suspension>
              <cfm>0</cfm>
              <erp>0.2</erp>
            </suspension>
          </ode>
        </physics>
      </joint>
      <static>0</static>
      <allow_auto_disable>1</allow_auto_disable>
      <plugin name='camera' filename='libFollowerPlugin.so'/>
      <pose>15.9037 -7.60867 0 0 -0 0</pose>
    </model>
    <state world_name='default'>
      <sim_time>108 233000000</sim_time>
      <real_time>159 423010135</real_time>
      <wall_time>1624096755 290172926</wall_time>
      <iterations>108233</iterations>
      <model name='cloverleaf_interchange'>
        <pose>-0.129569 0.117381 0 0 -0 0</pose>
        <scale>1 1 1</scale>
        <link name='link'>
          <pose>-0.129569 0.117381 0 0 -0 0</pose>
          <velocity>0 0 0 0 -0 0</velocity>
          <acceleration>0 0 0 0 -0 0</acceleration>
          <wrench>0 0 0 0 -0 0</wrench>
        </link>
      </model>
      <model name='ground_plane'>
        <pose>0 0 0 0 -0 0</pose>
        <scale>1 1 1</scale>
        <link name='link'>
          <pose>0 0 0 0 -0 0</pose>
          <velocity>0 0 0 0 -0 0</velocity>
          <acceleration>0 0 0 0 -0 0</acceleration>
          <wrench>0 0 0 0 -0 0</wrench>
        </link>
      </model>
      <model name='rover'>
        <pose>11.1735 -7.21081 0.691934 0.001983 0.001912 -1.54582</pose>
        <scale>1 1 1</scale>
        <link name='link_1'>
          <pose>11.2287 -7.20299 1.38172 0.001983 0.001912 -1.54582</pose>
          <velocity>-0.193394 0.001097 -0.002462 -0.00492 0.000404 -0.000646</velocity>
          <acceleration>0.216099 0.233714 -9.75398 -0.035915 0.041185 -0.165123</acceleration>
          <wrench>0.216099 0.233714 -9.75398 0 -0 0</wrench>
        </link>
        <model name='rover'>
          <pose>9.51994 -11.3244 -0.690903 -0.002981 0.001403 -1.28075</pose>
          <scale>1 1 1</scale>
          <link name='link_base'>
            <pose>11.0987 -7.205 0.704259 0.001983 0.001913 -1.54582</pose>
            <velocity>-0.193667 -0.002151 -0.002391 -0.004951 0.000317 -0.000717</velocity>
            <acceleration>0.096178 0.156588 -9.75829 -0.14716 0.160278 -0.03806</acceleration>
            <wrench>0.096178 0.156588 -9.75829 0 -0 0</wrench>
          </link>
          <link name='link_upper_body'>
            <pose>11.3048 -7.20781 0.748264 0.001983 0.001912 -1.54582</pose>
            <velocity>-0.19366 -0.002066 -0.002469 -0.004914 0.000409 -0.000649</velocity>
            <acceleration>0.13822 0.16535 -9.77214 -0.07279 0.092883 -0.179896</acceleration>
            <wrench>0.13822 0.16535 -9.77214 0 -0 0</wrench>
          </link>
          <link name='link_wheel_back_left'>
            <pose>10.2311 -6.3627 0.403321 -0.970729 -0.001905 1.59943</pose>
            <velocity>-0.193278 -0.003051 -0.006325 0.009055 -0.486848 -0.001645</velocity>
            <acceleration>-0.065953 0.063295 -9.75615 -0.164325 -0.004661 -0.023895</acceleration>
            <wrench>-0.065953 0.063295 -9.75615 0 -0 0</wrench>
          </link>
          <link name='link_wheel_back_right'>
            <pose>10.2808 -8.11122 0.403254 2.14222 0.001913 -1.54582</pose>
            <velocity>-0.194365 -0.003205 0.002426 0.006996 -0.482564 -0.001451</velocity>
            <acceleration>-0.179019 -0.112709 -9.57585 -0.648684 -0.385202 0.140222</acceleration>
            <wrench>-0.179019 -0.112709 -9.57585 0 -0 0</wrench>
          </link>
          <link name='link_wheel_front_left'>
            <pose>11.8834 -6.32512 0.403298 0.484915 -0.0019 1.60177</pose>
            <velocity>-0.193153 -0.004062 -0.007058 0.010067 -0.479737 -0.001547</velocity>
            <acceleration>0.07578 0.016298 -9.5413 -0.047306 -0.001209 -0.13439</acceleration>
            <wrench>0.07578 0.016298 -9.5413 0 -0 0</wrench>
          </link>
          <link name='link_wheel_front_right'>
            <pose>11.9039 -8.06402 0.408426 2.71725 0.001913 -1.54582</pose>
            <velocity>-0.194434 -0.004237 0.001565 0.005383 -0.415095 -0.001587</velocity>
            <acceleration>-0.133259 0.003434 -9.91632 0.055186 0.001798 -0.218427</acceleration>
            <wrench>-0.133259 0.003434 -9.91632 0 -0 0</wrench>
          </link>
        </model>
      </model>
      <light name='sun'>
        <pose>0 0 10 0 -0 0</pose>
      </light>
    </state>
    <gui fullscreen='0'>
      <camera name='user_camera'>
        <pose>26.4133 -21.0509 6.40421 0 0.275643 2.35619</pose>
        <view_controller>orbit</view_controller>
        <projection_type>perspective</projection_type>
      </camera>
    </gui>
  </world>
</sdf>
